Workbook

Sheet Presupuesto
C1: Presupuesto Mensual y Anual
B7: Instrucciones
B8: 1. Llena los espacios en azul con tu información
B9: 2. Clasifica tus gastos cómo Esencial/No Esencial (E/NE)
B10: 3. Revisa tu flujo de caja
B11: 4. Analiza tu presupuesto y optimiza tu toma decisiones con base a esto
B14: Ingresos | I14: Gastos | Z14: Escoge y suma cuáles son tus gastos esenciales y no esenciales
B15: ¿Cuáles son tus fuentes de ingreso? | D15: ¿Cada cuánto?* | E15: Monto | F15: Mensual | G15: Anual | I15: ¿Cuáles son tus gastos? | K15: E/NE | L15: ¿Cada cuánto?* | M15: Monto | N15: Mensual | O15: Anual | Q15: ¿Cuáles son tus gastos? | S15: E/NE | T15: ¿Cada cuánto?* | U15: Monto | V15: Mensual | W15: Anual
B16: Salario | D16: Mensual | E16: 2000 | F16: =+IF(D16="Mensual",E16,IF(D16="Bimensual",E16/2,IF(D16="Semestral",E16/6,IF(D16="Trimestral",E16/3,IF(D16="Anual",E16/12,""))))) -> 2000 | G16: =+IF(D16="Mensual",E16*12,IF(D16="Bimensual",E16*6,IF(D16="Semestral",E16*2,IF(D16="Trimestral",E16*4,IF(D16="Anual",E16,""))))) -> 24000 | I16: Hogar | Q16: Créditos/ Deudas | Z16: Tipo de Gasto | AA16: Valores
B17: Bonos | D17: Trimestral | E17: 100 | F17: =+IF(D17="Mensual",E17,IF(D17="Bimensual",E17/2,IF(D17="Semestral",E17/6,IF(D17="Trimestral",E17/3,IF(D17="Anual",E17/12,""))))) -> 33.333333 | G17: =+IF(D17="Mensual",E17*12,IF(D17="Bimensual",E17*6,IF(D17="Semestral",E17*2,IF(D17="Trimestral",E17*4,IF(D17="Anual",E17,""))))) -> 400 | I17: Arriendo | K17: E | L17: Mensual | M17: 400 | N17: =+IF(L17="Mensual",M17,IF(L17="Bimensual",M17/2,IF(L17="Semestral",M17/6,IF(L17="Trimestral",M17/3,IF(L17="Anual",M17/12,""))))) -> 400 | O17: =+IF(L17="Mensual",M17*12,IF(L17="Bimensual",M17*6,IF(L17="Semestral",M17*2,IF(L17="Trimestral",M17*4,IF(L17="Anual",M17,""))))) -> 4800 | Q17: Crédito Hipotecario | T17: Mensual | U17: 100 | V17: =+IF(T17="Mensual",U17,IF(T17="Bimensual",U17/2,IF(T17="Semestral",U17/6,IF(T17="Trimestral",U17/3,IF(T17="Anual",U17/12,""))))) -> 100 | W17: =+IF(T17="Mensual",U17*12,IF(T17="Bimensual",U17*6,IF(T17="Semestral",U17*2,IF(T17="Trimestral",U17*4,IF(T17="Anual",U17,""))))) -> 1200 | Y17: E | Z17: Esenciales | AA17: =SUMIF($K$17:$K$25,Y17,$O$17:$O$25)+SUMIF($K$28:$K$30,Y17,$O$28:$O$30)+SUMIF($K$33:$K$37,Y17,$O$33:$O$37)+SUMIF($S$23:$S$27,Y17,$W$23:$W$27)+SUMIF($S$30:$S$37,Y17,$W$30:$W$37) -> 13920
B18: Dividendos | D18: Anual | E18: 1000 | F18: =+IF(D18="Mensual",E18,IF(D18="Bimensual",E18/2,IF(D18="Semestral",E18/6,IF(D18="Trimestral",E18/3,IF(D18="Anual",E18/12,""))))) -> 83.333333 | G18: =+IF(D18="Mensual",E18*12,IF(D18="Bimensual",E18*6,IF(D18="Semestral",E18*2,IF(D18="Trimestral",E18*4,IF(D18="Anual",E18,""))))) -> 1000 | I18: Administración | K18: E | L18: Mensual | M18: 50 | N18: =+IF(L18="Mensual",M18,IF(L18="Bimensual",M18/2,IF(L18="Semestral",M18/6,IF(L18="Trimestral",M18/3,IF(L18="Anual",M18/12,""))))) -> 50 | O18: =+IF(L18="Mensual",M18*12,IF(L18="Bimensual",M18*6,IF(L18="Semestral",M18*2,IF(L18="Trimestral",M18*4,IF(L18="Anual",M18,""))))) -> 600 | Q18: Crédito Auto | T18: Mensual | U18: 0 | V18: =+IF(T18="Mensual",U18,IF(T18="Bimensual",U18/2,IF(T18="Semestral",U18/6,IF(T18="Trimestral",U18/3,IF(T18="Anual",U18/12,""))))) -> 0 | W18: =+IF(T18="Mensual",U18*12,IF(T18="Bimensual",U18*6,IF(T18="Semestral",U18*2,IF(T18="Trimestral",U18*4,IF(T18="Anual",U18,""))))) -> 0 | Y18: NE | Z18: No Esenciales | AA18: =SUMIF($K$17:$K$25,Y18,$O$17:$O$25)+SUMIF($K$28:$K$30,Y18,$O$28:$O$30)+SUMIF($K$33:$K$37,Y18,$O$33:$O$37)+SUMIF($S$23:$S$27,Y18,$W$23:$W$27)+SUMIF($S$30:$S$37,Y18,$W$30:$W$37) -> 4040
B19: Comisiones | D19: Bimensual | E19: 200 | F19: =+IF(D19="Mensual",E19,IF(D19="bimensual",E19/2,IF(D19="Semestral",E19/6,IF(D19="Trimestral",E19/3,IF(D19="Anual",E19/12,""))))) -> 100 | G19: =+IF(D19="Mensual",E19*12,IF(D19="bimensual",E19*6,IF(D19="Semestral",E19*2,IF(D19="Trimestral",E19*4,IF(D19="Anual",E19,""))))) -> 1200 | I19: Luz | K19: E | L19: Mensual | M19: 30 | N19: =+IF(L19="Mensual",M19,IF(L19="Bimensual",M19/2,IF(L19="Semestral",M19/6,IF(L19="Trimestral",M19/3,IF(L19="Anual",M19/12,""))))) -> 30 | O19: =+IF(L19="Mensual",M19*12,IF(L19="Bimensual",M19*6,IF(L19="Semestral",M19*2,IF(L19="Trimestral",M19*4,IF(L19="Anual",M19,""))))) -> 360 | Q19: Tarjeta de Crédito | T19: Mensual | U19: 50 | V19: =+IF(T19="Mensual",U19,IF(T19="Bimensual",U19/2,IF(T19="Semestral",U19/6,IF(T19="Trimestral",U19/3,IF(T19="Anual",U19/12,""))))) -> 50 | W19: =+IF(T19="Mensual",U19*12,IF(T19="Bimensual",U19*6,IF(T19="Semestral",U19*2,IF(T19="Trimestral",U19*4,IF(T19="Anual",U19,""))))) -> 600 | Z19: Crédito Deuda | AA19: =+W21 -> 2400
B20: Otros | D20: Mensual | E20: 500 | F20: =+IF(D20="Mensual",E20,IF(D20="Bimensual",E20/2,IF(D20="Semestral",E20/6,IF(D20="Trimestral",E20/3,IF(D20="Anual",E20/12,""))))) -> 500 | G20: =+IF(D20="Mensual",E20*12,IF(D20="Bimensual",E20*6,IF(D20="Semestral",E20*2,IF(D20="Trimestral",E20*4,IF(D20="Anual",E20,""))))) -> 6000 | I20: Agua | K20: E | L20: Bimensual | M20: 30 | N20: =+IF(L20="Mensual",M20,IF(L20="Bimensual",M20/2,IF(L20="Semestral",M20/6,IF(L20="Trimestral",M20/3,IF(L20="Anual",M20/12,""))))) -> 15 | O20: =+IF(L20="Mensual",M20*12,IF(L20="Bimensual",M20*6,IF(L20="Semestral",M20*2,IF(L20="Trimestral",M20*4,IF(L20="Anual",M20,""))))) -> 180 | Q20: Otro | T20: Mensual | U20: 50 | V20: =+IF(T20="Mensual",U20,IF(T20="Bimensual",U20/2,IF(T20="Semestral",U20/6,IF(T20="Trimestral",U20/3,IF(T20="Anual",U20/12,""))))) -> 50 | W20: =+IF(T20="Mensual",U20*12,IF(T20="Bimensual",U20*6,IF(T20="Semestral",U20*2,IF(T20="Trimestral",U20*4,IF(T20="Anual",U20,""))))) -> 600
B21: Total | E21: =+SUM(E16:E20) -> 3800 | F21: =+SUM(F16:F20) -> 2716.6667 | G21: =+SUM(G16:G20) -> 32600 | I21: Gas | K21: E | L21: Mensual | M21: 5 | N21: =+IF(L21="Mensual",M21,IF(L21="Bimensual",M21/2,IF(L21="Semestral",M21/6,IF(L21="Trimestral",M21/3,IF(L21="Anual",M21/12,""))))) -> 5 | O21: =+IF(L21="Mensual",M21*12,IF(L21="Bimensual",M21*6,IF(L21="Semestral",M21*2,IF(L21="Trimestral",M21*4,IF(L21="Anual",M21,""))))) -> 60 | Q21: Total | U21: =SUM(U17:U20) -> 200 | V21: =SUM(V17:V20) -> 200 | W21: =SUM(W17:W20) -> 2400
I22: Teléfono | K22: NE | L22: Mensual | M22: 20 | N22: =+IF(L22="Mensual",M22,IF(L22="Bimensual",M22/2,IF(L22="Semestral",M22/6,IF(L22="Trimestral",M22/3,IF(L22="Anual",M22/12,""))))) -> 20 | O22: =+IF(L22="Mensual",M22*12,IF(L22="Bimensual",M22*6,IF(L22="Semestral",M22*2,IF(L22="Trimestral",M22*4,IF(L22="Anual",M22,""))))) -> 240 | Q22: Entretenimiento
C23: * | D23: (Llena con "Mensual", "Bimensual","Trimestral", "Semestral", "Anual") | I23: Internet | K23: E | L23: Mensual | M23: 30 | N23: =+IF(L23="Mensual",M23,IF(L23="Bimensual",M23/2,IF(L23="Semestral",M23/6,IF(L23="Trimestral",M23/3,IF(L23="Anual",M23/12,""))))) -> 30 | O23: =+IF(L23="Mensual",M23*12,IF(L23="Bimensual",M23*6,IF(L23="Semestral",M23*2,IF(L23="Trimestral",M23*4,IF(L23="Anual",M23,""))))) -> 360 | Q23: Viajes | S23: NE | T23: Semestral | U23: 1000 | V23: =+IF(T23="Mensual",U23,IF(T23="Bimensual",U23/2,IF(T23="Semestral",U23/6,IF(T23="Trimestral",U23/3,IF(T23="Anual",U23/12,""))))) -> 166.66667 | W23: =+IF(T23="Mensual",U23*12,IF(T23="Bimensual",U23*6,IF(T23="Semestral",U23*2,IF(T23="Trimestral",U23*4,IF(T23="Anual",U23,""))))) -> 2000
I24: TV | K24: E | L24: Mensual | M24: 30 | N24: =+IF(L24="Mensual",M24,IF(L24="Bimensual",M24/2,IF(L24="Semestral",M24/6,IF(L24="Trimestral",M24/3,IF(L24="Anual",M24/12,""))))) -> 30 | O24: =+IF(L24="Mensual",M24*12,IF(L24="Bimensual",M24*6,IF(L24="Semestral",M24*2,IF(L24="Trimestral",M24*4,IF(L24="Anual",M24,""))))) -> 360 | Q24: Restaurantes | S24: NE | T24: Mensual | U24: 0 | V24: =+IF(T24="Mensual",U24,IF(T24="Bimensual",U24/2,IF(T24="Semestral",U24/6,IF(T24="Trimestral",U24/3,IF(T24="Anual",U24/12,""))))) -> 0 | W24: =+IF(T24="Mensual",U24*12,IF(T24="Bimensual",U24*6,IF(T24="Semestral",U24*2,IF(T24="Trimestral",U24*4,IF(T24="Anual",U24,""))))) -> 0 | Y24: Hogar | Z24: =+O26 -> 6960 | AB24: Salario | AC24: =+G16 -> 24000
I25: Otro | K25: NE | L25: Mensual | M25: 0 | N25: =+IF(L25="Mensual",M25,IF(L25="Bimensual",M25/2,IF(L25="Semestral",M25/6,IF(L25="Trimestral",M25/3,IF(L25="Anual",M25/12,""))))) -> 0 | O25: =+IF(L25="Mensual",M25*12,IF(L25="Bimensual",M25*6,IF(L25="Semestral",M25*2,IF(L25="Trimestral",M25*4,IF(L25="Anual",M25,""))))) -> 0 | Q25: Diversión | S25: NE | T25: Mensual | U25: 0 | V25: =+IF(T25="Mensual",U25,IF(T25="Bimensual",U25/2,IF(T25="Semestral",U25/6,IF(T25="Trimestral",U25/3,IF(T25="Anual",U25/12,""))))) -> 0 | W25: =+IF(T25="Mensual",U25*12,IF(T25="Bimensual",U25*6,IF(T25="Semestral",U25*2,IF(T25="Trimestral",U25*4,IF(T25="Anual",U25,""))))) -> 0 | Y25: Comida | Z25: =+O31 -> 9000 | AB25: Bonos | AC25: =+G17 -> 400
I26: Total | M26: =SUM(M17:M25) -> 595 | N26: =SUM(N17:N25) -> 580 | O26: =SUM(O17:O25) -> 6960 | Q26: Fiesta | S26: E | T26: Mensual | U26: 0 | V26: =+IF(T26="Mensual",U26,IF(T26="Bimensual",U26/2,IF(T26="Semestral",U26/6,IF(T26="Trimestral",U26/3,IF(T26="Anual",U26/12,""))))) -> 0 | W26: =+IF(T26="Mensual",U26*12,IF(T26="Bimensual",U26*6,IF(T26="Semestral",U26*2,IF(T26="Trimestral",U26*4,IF(T26="Anual",U26,""))))) -> 0 | Y26: Transporte | Z26: =+O38 -> 0 | AB26: Dividendos | AC26: =+G18 -> 1000
I27: Comida | Q27: Otros | S27: NE | T27: Mensual | U27: 0 | V27: =+IF(T27="Mensual",U27,IF(T27="Bimensual",U27/2,IF(T27="Semestral",U27/6,IF(T27="Trimestral",U27/3,IF(T27="Anual",U27/12,""))))) -> 0 | W27: =+IF(T27="Mensual",U27*12,IF(T27="Bimensual",U27*6,IF(T27="Semestral",U27*2,IF(T27="Trimestral",U27*4,IF(T27="Anual",U27,""))))) -> 0 | Y27: Créditos/ Deudas | Z27: =+W21 -> 2400 | AB27: Comisiones | AC27: =+G19 -> 1200
I28: Mercado | K28: E | L28: Mensual | M28: 600 | N28: =+IF(L28="Mensual",M28,IF(L28="Bimensual",M28/2,IF(L28="Semestral",M28/6,IF(L28="Trimestral",M28/3,IF(L28="Anual",M28/12,""))))) -> 600 | O28: =+IF(L28="Mensual",M28*12,IF(L28="Bimensual",M28*6,IF(L28="Semestral",M28*2,IF(L28="Trimestral",M28*4,IF(L28="Anual",M28,""))))) -> 7200 | Q28: Total | U28: =SUM(U23:U27) -> 1000 | V28: =SUM(V23:V27) -> 166.66667 | W28: =SUM(W23:W27) -> 2000 | Y28: Entretenimiento | Z28: =+W28 -> 2000 | AB28: Otros | AC28: =+G20 -> 6000
I29: Comidas por fuera | K29: NE | L29: Mensual | M29: 100 | N29: =+IF(L29="Mensual",M29,IF(L29="Bimensual",M29/2,IF(L29="Semestral",M29/6,IF(L29="Trimestral",M29/3,IF(L29="Anual",M29/12,""))))) -> 100 | O29: =+IF(L29="Mensual",M29*12,IF(L29="Bimensual",M29*6,IF(L29="Semestral",M29*2,IF(L29="Trimestral",M29*4,IF(L29="Anual",M29,""))))) -> 1200 | Q29: Familia | Y29: Familia | Z29: =+W38 -> 0
I30: Otro | K30: NE | L30: Mensual | M30: 50 | N30: =+IF(L30="Mensual",M30,IF(L30="Bimensual",M30/2,IF(L30="Semestral",M30/6,IF(L30="Trimestral",M30/3,IF(L30="Anual",M30/12,""))))) -> 50 | O30: =+IF(L30="Mensual",M30*12,IF(L30="Bimensual",M30*6,IF(L30="Semestral",M30*2,IF(L30="Trimestral",M30*4,IF(L30="Anual",M30,""))))) -> 600 | Q30: Colegios | S30: E | T30: Mensual | U30: 0 | V30: =+IF(T30="Mensual",U30,IF(T30="Bimensual",U30/2,IF(T30="Semestral",U30/6,IF(T30="Trimestral",U30/3,IF(T30="Anual",U30/12,""))))) -> 0 | W30: =+IF(T30="Mensual",U30*12,IF(T30="Bimensual",U30*6,IF(T30="Semestral",U30*2,IF(T30="Trimestral",U30*4,IF(T30="Anual",U30,""))))) -> 0
I31: Total | M31: =SUM(M28:M30) -> 750 | N31: =SUM(N28:N30) -> 750 | O31: =SUM(O28:O30) -> 9000 | Q31: Seguro Médico | S31: E | T31: Mensual | U31: 0 | V31: =+IF(T31="Mensual",U31,IF(T31="Bimensual",U31/2,IF(T31="Semestral",U31/6,IF(T31="Trimestral",U31/3,IF(T31="Anual",U31/12,""))))) -> 0 | W31: =+IF(T31="Mensual",U31*12,IF(T31="Bimensual",U31*6,IF(T31="Semestral",U31*2,IF(T31="Trimestral",U31*4,IF(T31="Anual",U31,""))))) -> 0
I32: Transporte | Q32: Otros Seguros | S32: NE | T32: Mensual | U32: 0 | V32: =+IF(T32="Mensual",U32,IF(T32="Bimensual",U32/2,IF(T32="Semestral",U32/6,IF(T32="Trimestral",U32/3,IF(T32="Anual",U32/12,""))))) -> 0 | W32: =+IF(T32="Mensual",U32*12,IF(T32="Bimensual",U32*6,IF(T32="Semestral",U32*2,IF(T32="Trimestral",U32*4,IF(T32="Anual",U32,""))))) -> 0
B33: Ingresa en este cuadro cuánto quisieras ahorrar (así no lo estés haciendo en este momento) | I33: Gasolina | K33: E | L33: Mensual | M33: 0 | N33: =+IF(L33="Mensual",M33,IF(L33="Bimensual",M33/2,IF(L33="Semestral",M33/6,IF(L33="Trimestral",M33/3,IF(L33="Anual",M33/12,""))))) -> 0 | O33: =+IF(L33="Mensual",M33*12,IF(L33="Bimensual",M33*6,IF(L33="Semestral",M33*2,IF(L33="Trimestral",M33*4,IF(L33="Anual",M33,""))))) -> 0 | Q33: Suscripciones (Netflix, Spotify) | S33: NE | T33: Mensual | U33: 0 | V33: =+IF(T33="Mensual",U33,IF(T33="Bimensual",U33/2,IF(T33="Semestral",U33/6,IF(T33="Trimestral",U33/3,IF(T33="Anual",U33/12,""))))) -> 0 | W33: =+IF(T33="Mensual",U33*12,IF(T33="Bimensual",U33*6,IF(T33="Semestral",U33*2,IF(T33="Trimestral",U33*4,IF(T33="Anual",U33,""))))) -> 0
I34: Taxi/Uber | K34: NE | L34: Mensual | M34: 0 | N34: =+IF(L34="Mensual",M34,IF(L34="Bimensual",M34/2,IF(L34="Semestral",M34/6,IF(L34="Trimestral",M34/3,IF(L34="Anual",M34/12,""))))) -> 0 | O34: =+IF(L34="Mensual",M34*12,IF(L34="Bimensual",M34*6,IF(L34="Semestral",M34*2,IF(L34="Trimestral",M34*4,IF(L34="Anual",M34,""))))) -> 0 | Q34: Gimnasio | S34: E | T34: Mensual | U34: 0 | V34: =+IF(T34="Mensual",U34,IF(T34="Bimensual",U34/2,IF(T34="Semestral",U34/6,IF(T34="Trimestral",U34/3,IF(T34="Anual",U34/12,""))))) -> 0 | W34: =+IF(T34="Mensual",U34*12,IF(T34="Bimensual",U34*6,IF(T34="Semestral",U34*2,IF(T34="Trimestral",U34*4,IF(T34="Anual",U34,""))))) -> 0
B35: Ahorro | I35: Mantenimiento auto | K35: E | L35: Mensual | M35: 0 | N35: =+IF(L35="Mensual",M35,IF(L35="Bimensual",M35/2,IF(L35="Semestral",M35/6,IF(L35="Trimestral",M35/3,IF(L35="Anual",M35/12,""))))) -> 0 | O35: =+IF(L35="Mensual",M35*12,IF(L35="Bimensual",M35*6,IF(L35="Semestral",M35*2,IF(L35="Trimestral",M35*4,IF(L35="Anual",M35,""))))) -> 0 | Q35: Impuestos | S35: E | T35: Anual | U35: 0 | V35: =+IF(T35="Mensual",U35,IF(T35="Bimensual",U35/2,IF(T35="Semestral",U35/6,IF(T35="Trimestral",U35/3,IF(T35="Anual",U35/12,""))))) -> 0 | W35: =+IF(T35="Mensual",U35*12,IF(T35="Bimensual",U35*6,IF(T35="Semestral",U35*2,IF(T35="Trimestral",U35*4,IF(T35="Anual",U35,""))))) -> 0
B36: ¿Cuánto quisieras ahorrar? | D36: ¿Cada cuánto?* | E36: Monto | F36: Mensual | G36: Anual | I36: Seguro auto | K36: NE | L36: Mensual | M36: 0 | N36: =+IF(L36="Mensual",M36,IF(L36="Bimensual",M36/2,IF(L36="Semestral",M36/6,IF(L36="Trimestral",M36/3,IF(L36="Anual",M36/12,""))))) -> 0 | O36: =+IF(L36="Mensual",M36*12,IF(L36="Bimensual",M36*6,IF(L36="Semestral",M36*2,IF(L36="Trimestral",M36*4,IF(L36="Anual",M36,""))))) -> 0 | Q36: Entretenimiento | S36: NE | T36: Mensual | U36: 0 | V36: =+IF(T36="Mensual",U36,IF(T36="Bimensual",U36/2,IF(T36="Semestral",U36/6,IF(T36="Trimestral",U36/3,IF(T36="Anual",U36/12,""))))) -> 0 | W36: =+IF(T36="Mensual",U36*12,IF(T36="Bimensual",U36*6,IF(T36="Semestral",U36*2,IF(T36="Trimestral",U36*4,IF(T36="Anual",U36,""))))) -> 0
B37: Ahorro | D37: Mensual | E37: 100 | F37: =+IF(D37="Mensual",E37,IF(D37="Bimensual",E37/2,IF(D37="Semestral",E37/6,IF(D37="Trimestral",E37/3,IF(D37="Anual",E37/12,""))))) -> 100 | G37: =+IF(D37="Mensual",E37*12,IF(D37="Bimensual",E37*6,IF(D37="Semestral",E37*2,IF(D37="Trimestral",E37*4,IF(D37="Anual",E37,""))))) -> 1200 | I37: Otro | K37: NE | L37: Mensual | M37: 0 | N37: =+IF(L37="Mensual",M37,IF(L37="Bimensual",M37/2,IF(L37="Semestral",M37/6,IF(L37="Trimestral",M37/3,IF(L37="Anual",M37/12,""))))) -> 0 | O37: =+IF(L37="Mensual",M37*12,IF(L37="Bimensual",M37*6,IF(L37="Semestral",M37*2,IF(L37="Trimestral",M37*4,IF(L37="Anual",M37,""))))) -> 0 | Q37: Otros (Ropa, Juguetes, etc…) | S37: NE | T37: Trimestral | U37: 0 | V37: =+IF(T37="Mensual",U37,IF(T37="Bimensual",U37/2,IF(T37="Semestral",U37/6,IF(T37="Trimestral",U37/3,IF(T37="Anual",U37/12,""))))) -> 0 | W37: =+IF(T37="Mensual",U37*12,IF(T37="Bimensual",U37*6,IF(T37="Semestral",U37*2,IF(T37="Trimestral",U37*4,IF(T37="Anual",U37,""))))) -> 0
B38: Total | E38: =+SUM(E37) -> 100 | F38: =+SUM(F37) -> 100 | G38: =+SUM(G37) -> 1200 | I38: Total | M38: =SUM(M33:M37) -> 0 | N38: =SUM(N33:N37) -> 0 | O38: =SUM(O33:O37) -> 0 | Q38: Total | U38: =SUM(U30:U37) -> 0 | V38: =SUM(V30:V37) -> 0 | W38: =SUM(W30:W37) -> 0
Q39: Total General | U39: =+U38+U28+U21+M38+M31+M26 -> 2545 | V39: =+V38+V21+N38+N31+N26+V28 -> 1696.6667 | W39: =+W38+W21+O38+O31+O26+W28 -> 20360
B42: Este Flujo de Caja te muestra cuánto te queda de dinero disponible al mes y al año después de cubrir todos tus gastos hoy en día
B44: Flujo de Caja Actual | I44: Tu Presupuesto
D45: Mensuales | F45: Anuales
B46: Ingresos | D46: =+F21 -> 2716.6667 | F46: =+G21 -> 32600
B48: Gastos | D48: =+V39 -> 1696.6667 | F48: =+W39 -> 20360
B50: Flujo De Caja Libre | D50: =+D46-D48 -> 1020 | F50: =+F46-F48 -> 12240
B53: Este Flujo de Caja con Ahorro te dice cuánto te queda para gastar después de guardar lo que quieres ahorrar
B55: Flujo de Caja Con Ahorro
...

Sheet Flujo de Caja
B7: Instrucciones
B8: 1. Con la información que agregaste en el presupuesto, este modelo de flujo de caja se creará solo pero con los mismos valores todos los meses.
B9: 2. Ajusta el flujo de acuerdo a tus ingresos y gastos. Por ejemplo, los impuestos no se pagan mensuales por igual, pon la totalidad del gasto en el mes que corresponde.
B10: 3. Esto te ayudará a organizarte financieramente de acuerdo al flujo que tengas cada mes.
B12: Ingresos | E12: Mes 1 | F12: Mes 1 | G12: Mes 2 | H12: Mes 3 | I12: Mes 4 | J12: Mes 5 | K12: Mes 6
E13: Ingresos | Y13: Escoge y suma cuáles son tus gastos esenciales y no esenciales
B14: Salario | D14: =+Presupuesto!F16 -> 2000 | E14: =+D14 -> 2000 | G14: =+D14 -> 2000 | H14: =+D14 -> 2000 | I14: =+D14 -> 2000 | J14: =+D14 -> 2000 | K14: =+D14 -> 2000
B15: Bonos | D15: =+Presupuesto!F17 -> 33.333333 | E15: =+D15 -> 33.333333 | G15: =+D15 -> 33.333333 | H15: =+D15 -> 33.333333 | I15: =+D15 -> 33.333333 | J15: =+D15 -> 33.333333 | K15: =+D15 -> 33.333333 | Y15: Tipo de Gasto | Z15: Valores
B16: Dividendos | D16: =+Presupuesto!F18 -> 83.333333 | E16: =+D16 -> 83.333333 | G16: =+D16 -> 83.333333 | H16: =+D16 -> 83.333333 | I16: =+D16 -> 83.333333 | J16: =+D16 -> 83.333333 | K16: =+D16 -> 83.333333 | Y16: Esenciales | Z16: =+O16+O17+O18+O19+O20+O27+O35+O34+O33+V29+V30+V31+V34 -> 0
B17: Comisiones | D17: =+Presupuesto!F19 -> 100 | E17: =+D17 -> 100 | G17: =+D17 -> 100 | H17: =+D17 -> 100 | I17: =+D17 -> 100 | J17: =+D17 -> 100 | K17: =+D17 -> 100 | Y17: No Esenciales | Z17: =+V18+V22+V23+V24+V25+V33+V35+V36+O28+O32+O33+O34+O23 -> 0
B18: Otros | D18: =+Presupuesto!F20 -> 500 | E18: =+D18 -> 500 | G18: =+D18 -> 500 | H18: =+D18 -> 500 | I18: =+D18 -> 500 | J18: =+D18 -> 500 | K18: =+D18 -> 500 | Y18: Crédito Deuda | Z18: =+V20 -> 0
B19: Total Ingresos | D19: =+SUM(D14:D18) -> 2716.6667 | E19: =+D19 -> 2716.6667 | G19: =+D19 -> 2716.6667 | H19: =+D19 -> 2716.6667 | I19: =+D19 -> 2716.6667 | J19: =+D19 -> 2716.6667 | K19: =+D19 -> 2716.6667
B20: Gastos | E20: Gastos
B21: Hogar
B22: Arriendo | D22: =+Presupuesto!N17 -> 400 | E22: =+D22 -> 400 | G22: =+D22 -> 400 | H22: =+D22 -> 400 | I22: =+D22 -> 400 | J22: =+D22 -> 400 | K22: =+D22 -> 400
B23: Administración | D23: =+Presupuesto!N18 -> 50 | E23: =+D23 -> 50 | G23: =+D23 -> 50 | H23: =+D23 -> 50 | I23: =+D23 -> 50 | J23: =+D23 -> 50 | K23: =+D23 -> 50 | X23: Hogar | Y23: =+O25 -> 0 | AA23: Salario | AB23: =+H15 -> 33.333333
B24: Luz | D24: =+Presupuesto!N19 -> 30 | E24: =+D24 -> 30 | G24: =+D24 -> 30 | H24: =+D24 -> 30 | I24: =+D24 -> 30 | J24: =+D24 -> 30 | K24: =+D24 -> 30 | X24: Comida | Y24: =+O30 -> 0 | AA24: Bonos | AB24: =+H16 -> 83.333333
B25: Agua | D25: =+Presupuesto!N20 -> 15 | E25: =+D25 -> 15 | G25: =+D25 -> 15 | H25: =+D25 -> 15 | I25: =+D25 -> 15 | J25: =+D25 -> 15 | K25: =+D25 -> 15 | X25: Transporte | Y25: =+O37 -> 0 | AA25: Dividendos | AB25: =+H17 -> 100
B26: Gas | D26: =+Presupuesto!N21 -> 5 | E26: =+D26 -> 5 | G26: =+D26 -> 5 | H26: =+D26 -> 5 | I26: =+D26 -> 5 | J26: =+D26 -> 5 | K26: =+D26 -> 5 | X26: Créditos/ Deudas | Y26: =+V20 -> 0 | AA26: Comisiones | AB26: =+H18 -> 500
B27: Teléfono | D27: =+Presupuesto!N22 -> 20 | E27: =+D27 -> 20 | G27: =+D27 -> 20 | H27: =+D27 -> 20 | I27: =+D27 -> 20 | J27: =+D27 -> 20 | K27: =+D27 -> 20 | X27: Entretenimiento | Y27: =+V27 -> 0 | AA27: Otros | AB27: =+H19 -> 2716.6667
B28: Internet | D28: =+Presupuesto!N23 -> 30 | E28: =+D28 -> 30 | G28: =+D28 -> 30 | H28: =+D28 -> 30 | I28: =+D28 -> 30 | J28: =+D28 -> 30 | K28: =+D28 -> 30 | X28: Familia | Y28: =+V37 -> 0
B29: TV | D29: =+Presupuesto!N24 -> 30 | E29: =+D29 -> 30 | G29: =+D29 -> 30 | H29: =+D29 -> 30 | I29: =+D29 -> 30 | J29: =+D29 -> 30 | K29: =+D29 -> 30
B30: Otro | D30: =+Presupuesto!N25 -> 0 | E30: =+D30 -> 0 | G30: =+D30 -> 0 | H30: =+D30 -> 0 | I30: =+D30 -> 0 | J30: =+D30 -> 0 | K30: =+D30 -> 0
B31: Total | D31: =+Presupuesto!N26 -> 580 | E31: =+D31 -> 580 | G31: =+D31 -> 580 | H31: =+D31 -> 580 | I31: =+D31 -> 580 | J31: =+D31 -> 580 | K31: =+D31 -> 580
B32: Comida
B33: Mercado | D33: =+Presupuesto!N28 -> 600 | E33: =+D33 -> 600 | G33: =+D33 -> 600 | H33: =+D33 -> 600 | I33: =+D33 -> 600 | J33: =+D33 -> 600 | K33: =+D33 -> 600
B34: Comidas por fuera | D34: =+Presupuesto!N29 -> 100 | E34: =+D34 -> 100 | G34: =+D34 -> 100 | H34: =+D34 -> 100 | I34: =+D34 -> 100 | J34: =+D34 -> 100 | K34: =+D34 -> 100
B35: Otro | D35: =+Presupuesto!N30 -> 50 | E35: =+D35 -> 50 | G35: =+D35 -> 50 | H35: =+D35 -> 50 | I35: =+D35 -> 50 | J35: =+D35 -> 50 | K35: =+D35 -> 50
B36: Total | D36: =+Presupuesto!N31 -> 750 | E36: =+D36 -> 750 | G36: =+D36 -> 750 | H36: =+D36 -> 750 | I36: =+D36 -> 750 | J36: =+D36 -> 750 | K36: =+D36 -> 750
B37: Transporte
B38: Gasolina | D38: =+Presupuesto!N33 -> 0 | E38: =+D38 -> 0 | G38: =+D38 -> 0 | H38: =+D38 -> 0 | I38: =+D38 -> 0 | J38: =+D38 -> 0 | K38: =+D38 -> 0
B39: Taxi/Uber | D39: =+Presupuesto!N34 -> 0 | E39: =+D39 -> 0 | G39: =+D39 -> 0 | H39: =+D39 -> 0 | I39: =+D39 -> 0 | J39: =+D39 -> 0 | K39: =+D39 -> 0
B40: Mantenimiento auto | D40: =+Presupuesto!N35 -> 0 | E40: =+D40 -> 0 | G40: =+D40 -> 0 | H40: =+D40 -> 0 | I40: =+D40 -> 0 | J40: =+D40 -> 0 | K40: =+D40 -> 0
B41: Seguro auto | D41: =+Presupuesto!N36 -> 0 | E41: =+D41 -> 0 | G41: =+D41 -> 0 | H41: =+D41 -> 0 | I41: =+D41 -> 0 | J41: =+D41 -> 0 | K41: =+D41 -> 0
B42: Otro | D42: =+Presupuesto!N37 -> 0 | E42: =+D42 -> 0 | G42: =+D42 -> 0 | H42: =+D42 -> 0 | I42: =+D42 -> 0 | J42: =+D42 -> 0 | K42: =+D42 -> 0
B43: Total | D43: =+Presupuesto!N38 -> 0 | E43: =+D43 -> 0 | G43: =+D43 -> 0 | H43: =+D43 -> 0 | I43: =+D43 -> 0 | J43: =+D43 -> 0 | K43: =+D43 -> 0
B44: Créditos/ Deudas
B45: Crédito Hipotecario | D45: =+Presupuesto!V17 -> 100 | E45: =+D45 -> 100 | G45: =+D45 -> 100 | H45: =+D45 -> 100 | I45: =+D45 -> 100 | J45: =+D45 -> 100 | K45: =+D45 -> 100
B46: Crédito Auto | D46: =+Presupuesto!V18 -> 0 | E46: =+D46 -> 0 | G46: =+D46 -> 0 | H46: =+D46 -> 0 | I46: =+D46 -> 0 | J46: =+D46 -> 0 | K46: =+D46 -> 0
B47: Tarjeta de Crédito | D47: =+Presupuesto!V19 -> 50 | E47: =+D47 -> 50 | G47: =+D47 -> 50 | H47: =+D47 -> 50 | I47: =+D47 -> 50 | J47: =+D47 -> 50 | K47: =+D47 -> 50
...

Sheet Real vs presupuestado
B8: Real | F8: Presupuestado
B10: Ingresos | F10: Ingresos | G10: =+'Flujo de Caja'!E19 -> 2716.6667
B11: Gastos | F11: Gastos | G11: =+'Flujo de Caja'!E67 -> 1696.6667
B12: Flujo de caja | C12: =+C10-C11 -> 0 | F12: Flujo de caja | G12: =+G10-G11 -> 1020

Sheet Hoja1
A1: Periodicidad
A2: Mensual
A3: Bimensual
A4: Trimestral
A5: Semestral
A6: Anual
A9: Escencial/No Escencial
A10: E
A11: NE
